[2024-10-16T09:54:50.011+0000] {taskinstance.py:1087} INFO - Dependencies all met for <TaskInstance: exchange_rate_usd_kzt_dag.insert_rate scheduled__2024-03-25T00:00:00+00:00 [queued]>
[2024-10-16T09:54:50.033+0000] {taskinstance.py:1087} INFO - Dependencies all met for <TaskInstance: exchange_rate_usd_kzt_dag.insert_rate scheduled__2024-03-25T00:00:00+00:00 [queued]>
[2024-10-16T09:54:50.034+0000] {taskinstance.py:1283} INFO - 
--------------------------------------------------------------------------------
[2024-10-16T09:54:50.035+0000] {taskinstance.py:1284} INFO - Starting attempt 1 of 1
[2024-10-16T09:54:50.036+0000] {taskinstance.py:1285} INFO - 
--------------------------------------------------------------------------------
[2024-10-16T09:54:50.078+0000] {taskinstance.py:1304} INFO - Executing <Task(PostgresOperator): insert_rate> on 2024-03-25 00:00:00+00:00
[2024-10-16T09:54:50.090+0000] {standard_task_runner.py:55} INFO - Started process 8369 to run task
[2024-10-16T09:54:50.105+0000] {standard_task_runner.py:82} INFO - Running: ['***', 'tasks', 'run', 'exchange_rate_usd_kzt_dag', 'insert_rate', 'scheduled__2024-03-25T00:00:00+00:00', '--job-id', '1611', '--raw', '--subdir', 'DAGS_FOLDER/exchange_rates/__init__.py', '--cfg-path', '/tmp/tmp22ci1gg_']
[2024-10-16T09:54:50.107+0000] {standard_task_runner.py:83} INFO - Job 1611: Subtask insert_rate
[2024-10-16T09:54:50.303+0000] {task_command.py:389} INFO - Running <TaskInstance: exchange_rate_usd_kzt_dag.insert_rate scheduled__2024-03-25T00:00:00+00:00 [running]> on host 63ee4fa64e74
[2024-10-16T09:54:50.389+0000] {warnings.py:110} WARNING - /home/***/.local/lib/python3.7/site-packages/***/utils/context.py:205: AirflowContextDeprecationWarning: Accessing 'execution_date' from the template is deprecated and will be removed in a future version. Please use 'data_interval_start' or 'logical_date' instead.
  warnings.warn(_create_deprecation_warning(key, self._deprecation_replacements[key]))

[2024-10-16T09:54:50.505+0000] {taskinstance.py:1513} INFO - Exporting the following env vars:
AIRFLOW_CTX_DAG_OWNER=***
AIRFLOW_CTX_DAG_ID=exchange_rate_usd_kzt_dag
AIRFLOW_CTX_TASK_ID=insert_rate
AIRFLOW_CTX_EXECUTION_DATE=2024-03-25T00:00:00+00:00
AIRFLOW_CTX_TRY_NUMBER=1
AIRFLOW_CTX_DAG_RUN_ID=scheduled__2024-03-25T00:00:00+00:00
[2024-10-16T09:54:50.510+0000] {sql.py:253} INFO - Executing: INSERT INTO
    currency_exchange_rates
VALUES ('USD', 'KZT', 449.96017897, '2024-03-25')
ON CONFLICT (base, currency, date) DO
    UPDATE
        SET rate = excluded.rate;
[2024-10-16T09:54:50.529+0000] {base.py:73} INFO - Using connection ID 'postgres_default' for task execution.
[2024-10-16T09:54:50.981+0000] {base.py:73} INFO - Using connection ID 'postgres_default' for task execution.
[2024-10-16T09:54:50.995+0000] {sql.py:364} INFO - Running statement: INSERT INTO
    currency_exchange_rates
VALUES ('USD', 'KZT', 449.96017897, '2024-03-25')
ON CONFLICT (base, currency, date) DO
    UPDATE
        SET rate = excluded.rate;, parameters: None
[2024-10-16T09:54:51.000+0000] {sql.py:373} INFO - Rows affected: 1
[2024-10-16T09:54:51.023+0000] {taskinstance.py:1327} INFO - Marking task as SUCCESS. dag_id=exchange_rate_usd_kzt_dag, task_id=insert_rate, execution_date=20240325T000000, start_date=20241016T095450, end_date=20241016T095451
[2024-10-16T09:54:51.066+0000] {local_task_job.py:159} INFO - Task exited with return code 0
[2024-10-16T09:54:51.105+0000] {taskinstance.py:2582} INFO - 0 downstream tasks scheduled from follow-on schedule check
[2024-10-16T10:04:44.197+0000] {taskinstance.py:1087} INFO - Dependencies all met for <TaskInstance: exchange_rate_usd_kzt_dag.insert_rate scheduled__2024-03-25T00:00:00+00:00 [queued]>
[2024-10-16T10:04:44.212+0000] {taskinstance.py:1087} INFO - Dependencies all met for <TaskInstance: exchange_rate_usd_kzt_dag.insert_rate scheduled__2024-03-25T00:00:00+00:00 [queued]>
[2024-10-16T10:04:44.213+0000] {taskinstance.py:1283} INFO - 
--------------------------------------------------------------------------------
[2024-10-16T10:04:44.213+0000] {taskinstance.py:1284} INFO - Starting attempt 1 of 1
[2024-10-16T10:04:44.214+0000] {taskinstance.py:1285} INFO - 
--------------------------------------------------------------------------------
[2024-10-16T10:04:44.252+0000] {taskinstance.py:1304} INFO - Executing <Task(PostgresOperator): insert_rate> on 2024-03-25 00:00:00+00:00
[2024-10-16T10:04:44.266+0000] {standard_task_runner.py:55} INFO - Started process 10922 to run task
[2024-10-16T10:04:44.300+0000] {standard_task_runner.py:82} INFO - Running: ['***', 'tasks', 'run', 'exchange_rate_usd_kzt_dag', 'insert_rate', 'scheduled__2024-03-25T00:00:00+00:00', '--job-id', '2324', '--raw', '--subdir', 'DAGS_FOLDER/RUS_DAG.py', '--cfg-path', '/tmp/tmpzb2248j8']
[2024-10-16T10:04:44.301+0000] {standard_task_runner.py:83} INFO - Job 2324: Subtask insert_rate
[2024-10-16T10:04:44.422+0000] {task_command.py:389} INFO - Running <TaskInstance: exchange_rate_usd_kzt_dag.insert_rate scheduled__2024-03-25T00:00:00+00:00 [running]> on host 63ee4fa64e74
[2024-10-16T10:04:44.465+0000] {abstractoperator.py:596} ERROR - Exception rendering Jinja template for task 'insert_rate', field 'sql'. Template: 'sql/insert_rate.sql'
Traceback (most recent call last):
  File "/home/airflow/.local/lib/python3.7/site-packages/airflow/models/abstractoperator.py", line 589, in _do_render_template_fields
    seen_oids,
  File "/home/airflow/.local/lib/python3.7/site-packages/airflow/models/abstractoperator.py", line 640, in render_template
    template = jinja_env.get_template(value)
  File "/home/airflow/.local/lib/python3.7/site-packages/jinja2/environment.py", line 1010, in get_template
    return self._load_template(name, globals)
  File "/home/airflow/.local/lib/python3.7/site-packages/jinja2/environment.py", line 969, in _load_template
    template = self.loader.load(self, name, self.make_globals(globals))
  File "/home/airflow/.local/lib/python3.7/site-packages/jinja2/loaders.py", line 126, in load
    source, filename, uptodate = self.get_source(environment, name)
  File "/home/airflow/.local/lib/python3.7/site-packages/jinja2/loaders.py", line 218, in get_source
    raise TemplateNotFound(template)
jinja2.exceptions.TemplateNotFound: sql/insert_rate.sql
[2024-10-16T10:04:44.467+0000] {taskinstance.py:1772} ERROR - Task failed with exception
Traceback (most recent call last):
  File "/home/airflow/.local/lib/python3.7/site-packages/airflow/models/taskinstance.py", line 1378, in _run_raw_task
    self._execute_task_with_callbacks(context, test_mode)
  File "/home/airflow/.local/lib/python3.7/site-packages/airflow/models/taskinstance.py", line 1497, in _execute_task_with_callbacks
    task_orig = self.render_templates(context=context)
  File "/home/airflow/.local/lib/python3.7/site-packages/airflow/models/taskinstance.py", line 2119, in render_templates
    original_task.render_template_fields(context)
  File "/home/airflow/.local/lib/python3.7/site-packages/airflow/models/baseoperator.py", line 1196, in render_template_fields
    self._do_render_template_fields(self, self.template_fields, context, jinja_env, set())
  File "/home/airflow/.local/lib/python3.7/site-packages/airflow/utils/session.py", line 75, in wrapper
    return func(*args, session=session, **kwargs)
  File "/home/airflow/.local/lib/python3.7/site-packages/airflow/models/abstractoperator.py", line 589, in _do_render_template_fields
    seen_oids,
  File "/home/airflow/.local/lib/python3.7/site-packages/airflow/models/abstractoperator.py", line 640, in render_template
    template = jinja_env.get_template(value)
  File "/home/airflow/.local/lib/python3.7/site-packages/jinja2/environment.py", line 1010, in get_template
    return self._load_template(name, globals)
  File "/home/airflow/.local/lib/python3.7/site-packages/jinja2/environment.py", line 969, in _load_template
    template = self.loader.load(self, name, self.make_globals(globals))
  File "/home/airflow/.local/lib/python3.7/site-packages/jinja2/loaders.py", line 126, in load
    source, filename, uptodate = self.get_source(environment, name)
  File "/home/airflow/.local/lib/python3.7/site-packages/jinja2/loaders.py", line 218, in get_source
    raise TemplateNotFound(template)
jinja2.exceptions.TemplateNotFound: sql/insert_rate.sql
[2024-10-16T10:04:44.483+0000] {taskinstance.py:1327} INFO - Marking task as FAILED. dag_id=exchange_rate_usd_kzt_dag, task_id=insert_rate, execution_date=20240325T000000, start_date=20241016T100444, end_date=20241016T100444
[2024-10-16T10:04:44.499+0000] {standard_task_runner.py:105} ERROR - Failed to execute job 2324 for task insert_rate (sql/insert_rate.sql; 10922)
[2024-10-16T10:04:44.542+0000] {local_task_job.py:159} INFO - Task exited with return code 1
[2024-10-16T10:04:44.563+0000] {taskinstance.py:2582} INFO - 0 downstream tasks scheduled from follow-on schedule check
