[2024-10-16T09:55:18.708+0000] {taskinstance.py:1087} INFO - Dependencies all met for <TaskInstance: exchange_rate_usd_kzt_dag.insert_rate scheduled__2024-04-29T00:00:00+00:00 [queued]>
[2024-10-16T09:55:18.723+0000] {taskinstance.py:1087} INFO - Dependencies all met for <TaskInstance: exchange_rate_usd_kzt_dag.insert_rate scheduled__2024-04-29T00:00:00+00:00 [queued]>
[2024-10-16T09:55:18.723+0000] {taskinstance.py:1283} INFO - 
--------------------------------------------------------------------------------
[2024-10-16T09:55:18.724+0000] {taskinstance.py:1284} INFO - Starting attempt 1 of 1
[2024-10-16T09:55:18.724+0000] {taskinstance.py:1285} INFO - 
--------------------------------------------------------------------------------
[2024-10-16T09:55:18.746+0000] {taskinstance.py:1304} INFO - Executing <Task(PostgresOperator): insert_rate> on 2024-04-29 00:00:00+00:00
[2024-10-16T09:55:18.752+0000] {standard_task_runner.py:55} INFO - Started process 8611 to run task
[2024-10-16T09:55:18.757+0000] {standard_task_runner.py:82} INFO - Running: ['***', 'tasks', 'run', 'exchange_rate_usd_kzt_dag', 'insert_rate', 'scheduled__2024-04-29T00:00:00+00:00', '--job-id', '1701', '--raw', '--subdir', 'DAGS_FOLDER/exchange_rates/__init__.py', '--cfg-path', '/tmp/tmppeg098_f']
[2024-10-16T09:55:18.759+0000] {standard_task_runner.py:83} INFO - Job 1701: Subtask insert_rate
[2024-10-16T09:55:18.861+0000] {task_command.py:389} INFO - Running <TaskInstance: exchange_rate_usd_kzt_dag.insert_rate scheduled__2024-04-29T00:00:00+00:00 [running]> on host 63ee4fa64e74
[2024-10-16T09:55:18.924+0000] {warnings.py:110} WARNING - /home/***/.local/lib/python3.7/site-packages/***/utils/context.py:205: AirflowContextDeprecationWarning: Accessing 'execution_date' from the template is deprecated and will be removed in a future version. Please use 'data_interval_start' or 'logical_date' instead.
  warnings.warn(_create_deprecation_warning(key, self._deprecation_replacements[key]))

[2024-10-16T09:55:19.023+0000] {taskinstance.py:1513} INFO - Exporting the following env vars:
AIRFLOW_CTX_DAG_OWNER=***
AIRFLOW_CTX_DAG_ID=exchange_rate_usd_kzt_dag
AIRFLOW_CTX_TASK_ID=insert_rate
AIRFLOW_CTX_EXECUTION_DATE=2024-04-29T00:00:00+00:00
AIRFLOW_CTX_TRY_NUMBER=1
AIRFLOW_CTX_DAG_RUN_ID=scheduled__2024-04-29T00:00:00+00:00
[2024-10-16T09:55:19.025+0000] {sql.py:253} INFO - Executing: INSERT INTO
    currency_exchange_rates
VALUES ('USD', 'KZT', 441.60979177, '2024-04-29')
ON CONFLICT (base, currency, date) DO
    UPDATE
        SET rate = excluded.rate;
[2024-10-16T09:55:19.043+0000] {base.py:73} INFO - Using connection ID 'postgres_default' for task execution.
[2024-10-16T09:55:19.370+0000] {base.py:73} INFO - Using connection ID 'postgres_default' for task execution.
[2024-10-16T09:55:19.383+0000] {sql.py:364} INFO - Running statement: INSERT INTO
    currency_exchange_rates
VALUES ('USD', 'KZT', 441.60979177, '2024-04-29')
ON CONFLICT (base, currency, date) DO
    UPDATE
        SET rate = excluded.rate;, parameters: None
[2024-10-16T09:55:19.392+0000] {sql.py:373} INFO - Rows affected: 1
[2024-10-16T09:55:19.422+0000] {taskinstance.py:1327} INFO - Marking task as SUCCESS. dag_id=exchange_rate_usd_kzt_dag, task_id=insert_rate, execution_date=20240429T000000, start_date=20241016T095518, end_date=20241016T095519
[2024-10-16T09:55:19.472+0000] {local_task_job.py:159} INFO - Task exited with return code 0
[2024-10-16T09:55:19.504+0000] {taskinstance.py:2582} INFO - 0 downstream tasks scheduled from follow-on schedule check
[2024-10-16T10:05:16.675+0000] {taskinstance.py:1087} INFO - Dependencies all met for <TaskInstance: exchange_rate_usd_kzt_dag.insert_rate scheduled__2024-04-29T00:00:00+00:00 [queued]>
[2024-10-16T10:05:16.685+0000] {taskinstance.py:1087} INFO - Dependencies all met for <TaskInstance: exchange_rate_usd_kzt_dag.insert_rate scheduled__2024-04-29T00:00:00+00:00 [queued]>
[2024-10-16T10:05:16.685+0000] {taskinstance.py:1283} INFO - 
--------------------------------------------------------------------------------
[2024-10-16T10:05:16.686+0000] {taskinstance.py:1284} INFO - Starting attempt 1 of 1
[2024-10-16T10:05:16.687+0000] {taskinstance.py:1285} INFO - 
--------------------------------------------------------------------------------
[2024-10-16T10:05:16.701+0000] {taskinstance.py:1304} INFO - Executing <Task(PostgresOperator): insert_rate> on 2024-04-29 00:00:00+00:00
[2024-10-16T10:05:16.705+0000] {standard_task_runner.py:55} INFO - Started process 11159 to run task
[2024-10-16T10:05:16.709+0000] {standard_task_runner.py:82} INFO - Running: ['***', 'tasks', 'run', 'exchange_rate_usd_kzt_dag', 'insert_rate', 'scheduled__2024-04-29T00:00:00+00:00', '--job-id', '2418', '--raw', '--subdir', 'DAGS_FOLDER/RUS_DAG.py', '--cfg-path', '/tmp/tmp4yj35ase']
[2024-10-16T10:05:16.710+0000] {standard_task_runner.py:83} INFO - Job 2418: Subtask insert_rate
[2024-10-16T10:05:16.787+0000] {task_command.py:389} INFO - Running <TaskInstance: exchange_rate_usd_kzt_dag.insert_rate scheduled__2024-04-29T00:00:00+00:00 [running]> on host 63ee4fa64e74
[2024-10-16T10:05:16.826+0000] {abstractoperator.py:596} ERROR - Exception rendering Jinja template for task 'insert_rate', field 'sql'. Template: 'sql/insert_rate.sql'
Traceback (most recent call last):
  File "/home/airflow/.local/lib/python3.7/site-packages/airflow/models/abstractoperator.py", line 589, in _do_render_template_fields
    seen_oids,
  File "/home/airflow/.local/lib/python3.7/site-packages/airflow/models/abstractoperator.py", line 640, in render_template
    template = jinja_env.get_template(value)
  File "/home/airflow/.local/lib/python3.7/site-packages/jinja2/environment.py", line 1010, in get_template
    return self._load_template(name, globals)
  File "/home/airflow/.local/lib/python3.7/site-packages/jinja2/environment.py", line 969, in _load_template
    template = self.loader.load(self, name, self.make_globals(globals))
  File "/home/airflow/.local/lib/python3.7/site-packages/jinja2/loaders.py", line 126, in load
    source, filename, uptodate = self.get_source(environment, name)
  File "/home/airflow/.local/lib/python3.7/site-packages/jinja2/loaders.py", line 218, in get_source
    raise TemplateNotFound(template)
jinja2.exceptions.TemplateNotFound: sql/insert_rate.sql
[2024-10-16T10:05:16.828+0000] {taskinstance.py:1772} ERROR - Task failed with exception
Traceback (most recent call last):
  File "/home/airflow/.local/lib/python3.7/site-packages/airflow/models/taskinstance.py", line 1378, in _run_raw_task
    self._execute_task_with_callbacks(context, test_mode)
  File "/home/airflow/.local/lib/python3.7/site-packages/airflow/models/taskinstance.py", line 1497, in _execute_task_with_callbacks
    task_orig = self.render_templates(context=context)
  File "/home/airflow/.local/lib/python3.7/site-packages/airflow/models/taskinstance.py", line 2119, in render_templates
    original_task.render_template_fields(context)
  File "/home/airflow/.local/lib/python3.7/site-packages/airflow/models/baseoperator.py", line 1196, in render_template_fields
    self._do_render_template_fields(self, self.template_fields, context, jinja_env, set())
  File "/home/airflow/.local/lib/python3.7/site-packages/airflow/utils/session.py", line 75, in wrapper
    return func(*args, session=session, **kwargs)
  File "/home/airflow/.local/lib/python3.7/site-packages/airflow/models/abstractoperator.py", line 589, in _do_render_template_fields
    seen_oids,
  File "/home/airflow/.local/lib/python3.7/site-packages/airflow/models/abstractoperator.py", line 640, in render_template
    template = jinja_env.get_template(value)
  File "/home/airflow/.local/lib/python3.7/site-packages/jinja2/environment.py", line 1010, in get_template
    return self._load_template(name, globals)
  File "/home/airflow/.local/lib/python3.7/site-packages/jinja2/environment.py", line 969, in _load_template
    template = self.loader.load(self, name, self.make_globals(globals))
  File "/home/airflow/.local/lib/python3.7/site-packages/jinja2/loaders.py", line 126, in load
    source, filename, uptodate = self.get_source(environment, name)
  File "/home/airflow/.local/lib/python3.7/site-packages/jinja2/loaders.py", line 218, in get_source
    raise TemplateNotFound(template)
jinja2.exceptions.TemplateNotFound: sql/insert_rate.sql
[2024-10-16T10:05:16.839+0000] {taskinstance.py:1327} INFO - Marking task as FAILED. dag_id=exchange_rate_usd_kzt_dag, task_id=insert_rate, execution_date=20240429T000000, start_date=20241016T100516, end_date=20241016T100516
[2024-10-16T10:05:16.851+0000] {standard_task_runner.py:105} ERROR - Failed to execute job 2418 for task insert_rate (sql/insert_rate.sql; 11159)
[2024-10-16T10:05:16.888+0000] {local_task_job.py:159} INFO - Task exited with return code 1
[2024-10-16T10:05:16.908+0000] {taskinstance.py:2582} INFO - 0 downstream tasks scheduled from follow-on schedule check
