[2024-10-14T21:44:23.624+0000] {taskinstance.py:1087} INFO - Dependencies all met for <TaskInstance: first_dag.random_dice scheduled__2024-10-10T00:00:00+00:00 [queued]>
[2024-10-14T21:44:23.639+0000] {taskinstance.py:1087} INFO - Dependencies all met for <TaskInstance: first_dag.random_dice scheduled__2024-10-10T00:00:00+00:00 [queued]>
[2024-10-14T21:44:23.640+0000] {taskinstance.py:1283} INFO - 
--------------------------------------------------------------------------------
[2024-10-14T21:44:23.640+0000] {taskinstance.py:1284} INFO - Starting attempt 3 of 3
[2024-10-14T21:44:23.641+0000] {taskinstance.py:1285} INFO - 
--------------------------------------------------------------------------------
[2024-10-14T21:44:23.663+0000] {taskinstance.py:1304} INFO - Executing <Task(PythonOperator): random_dice> on 2024-10-10 00:00:00+00:00
[2024-10-14T21:44:23.668+0000] {standard_task_runner.py:55} INFO - Started process 20790 to run task
[2024-10-14T21:44:23.674+0000] {standard_task_runner.py:82} INFO - Running: ['***', 'tasks', 'run', 'first_dag', 'random_dice', 'scheduled__2024-10-10T00:00:00+00:00', '--job-id', '9', '--raw', '--subdir', 'DAGS_FOLDER/first_dag.py', '--cfg-path', '/tmp/tmpqlx0ps2c']
[2024-10-14T21:44:23.675+0000] {standard_task_runner.py:83} INFO - Job 9: Subtask random_dice
[2024-10-14T21:44:23.787+0000] {task_command.py:389} INFO - Running <TaskInstance: first_dag.random_dice scheduled__2024-10-10T00:00:00+00:00 [running]> on host 63ee4fa64e74
[2024-10-14T21:44:23.936+0000] {taskinstance.py:1513} INFO - Exporting the following env vars:
AIRFLOW_CTX_DAG_OWNER=***
AIRFLOW_CTX_DAG_ID=first_dag
AIRFLOW_CTX_TASK_ID=random_dice
AIRFLOW_CTX_EXECUTION_DATE=2024-10-10T00:00:00+00:00
AIRFLOW_CTX_TRY_NUMBER=3
AIRFLOW_CTX_DAG_RUN_ID=scheduled__2024-10-10T00:00:00+00:00
[2024-10-14T21:44:23.939+0000] {taskinstance.py:1772} ERROR - Task failed with exception
Traceback (most recent call last):
  File "/home/airflow/.local/lib/python3.7/site-packages/airflow/operators/python.py", line 175, in execute
    return_value = self.execute_callable()
  File "/home/airflow/.local/lib/python3.7/site-packages/airflow/operators/python.py", line 192, in execute_callable
    return self.python_callable(*self.op_args, **self.op_kwargs)
  File "/opt/airflow/dags/first_dag.py", line 17, in random_dice
    raise ValueError(f'Odd {val}')
ValueError: Odd 1
[2024-10-14T21:44:23.953+0000] {taskinstance.py:1327} INFO - Marking task as FAILED. dag_id=first_dag, task_id=random_dice, execution_date=20241010T000000, start_date=20241014T214423, end_date=20241014T214423
[2024-10-14T21:44:23.981+0000] {standard_task_runner.py:105} ERROR - Failed to execute job 9 for task random_dice (Odd 1; 20790)
[2024-10-14T21:44:24.017+0000] {local_task_job.py:159} INFO - Task exited with return code 1
[2024-10-14T21:44:24.059+0000] {taskinstance.py:2582} INFO - 0 downstream tasks scheduled from follow-on schedule check
